[pid: 13134|app: 0|req: 1/1] 192.168.1.16 () {42 vars in 792 bytes} [Tue Mar 14 13:39:45 2017] GET / => generated 3156 bytes in 43 msecs (HTTP/1.1 200) 3 headers in 283 bytes (1 switches on core 0)
[pid: 13134|app: 0|req: 2/2] 192.168.1.16 () {50 vars in 978 bytes} [Tue Mar 14 13:39:49 2017] POST / => generated 217 bytes in 352 msecs (HTTP/1.1 302) 4 headers in 606 bytes (1 switches on core 0)
[pid: 13134|app: 0|req: 3/3] 192.168.1.16 () {46 vars in 1151 bytes} [Tue Mar 14 13:39:50 2017] GET /log/ => generated 11840 bytes in 46 msecs (HTTP/1.1 200) 3 headers in 492 bytes (1 switches on core 0)
[pid: 13134|app: 0|req: 4/4] 192.168.1.16 () {44 vars in 1053 bytes} [Tue Mar 14 13:39:51 2017] GET /user/ => generated 13000 bytes in 44 msecs (HTTP/1.1 200) 2 headers in 82 bytes (1 switches on core 0)
[pid: 13134|app: 0|req: 5/5] 192.168.1.16 () {44 vars in 1058 bytes} [Tue Mar 14 13:39:52 2017] GET /domain/ => generated 9042 bytes in 44 msecs (HTTP/1.1 200) 2 headers in 81 bytes (1 switches on core 0)
[pid: 13134|app: 0|req: 6/6] 192.168.1.16 () {40 vars in 607 bytes} [Tue Mar 14 13:48:01 2017] GET / => generated 3156 bytes in 4 msecs (HTTP/1.1 200) 3 headers in 283 bytes (1 switches on core 0)
[pid: 13134|app: 0|req: 7/7] 192.168.1.16 () {40 vars in 540 bytes} [Tue Mar 14 13:48:02 2017] GET /favicon.ico => generated 233 bytes in 15 msecs (HTTP/1.1 404) 2 headers in 72 bytes (1 switches on core 0)
[pid: 13133|app: 0|req: 1/8] 192.168.1.16 () {40 vars in 541 bytes} [Tue Mar 14 13:49:06 2017] GET /favicon.ico => generated 233 bytes in 20 msecs (HTTP/1.1 404) 2 headers in 72 bytes (1 switches on core 0)
SIGINT/SIGQUIT received...killing workers...
worker 2 buried after 1 seconds
worker 1 buried after 2 seconds
goodbye to uWSGI.
*** Starting uWSGI 2.0.14 (64bit) on [Tue Mar 14 14:00:29 2017] ***
compiled with version: 4.8.4 on 10 March 2017 11:44:01
os: Linux-3.13.0-32-generic #57-Ubuntu SMP Tue Jul 15 03:51:08 UTC 2014
nodename: ubuntu-web
machine: x86_64
clock source: unix
pcre jit disabled
detected number of CPU cores: 16
current working directory: /data/www/code
writing pidfile to /data/www/code//uwsgi.pid
detected binary path: /usr/local/bin/uwsgi
setgid() to 1003
set additional group 33 (www-data)
setuid() to 1003
chdir() to /data/www/code/
your processes number limit is 95816
your memory page size is 4096 bytes
detected max file descriptor number: 1000000
lock engine: pthread robust mutexes
thunder lock: disabled (you can enable it with --thunder-lock)
uwsgi socket 0 bound to TCP address 127.0.0.1:9090 fd 3
Python version: 2.7.6 (default, Oct 26 2016, 20:33:43)  [GCC 4.8.4]
Set PythonHome to /data/www/code/venv
*** Python threads support is disabled. You can enable it with --enable-threads ***
Python main interpreter initialized at 0x1ca10f0
your server socket listen backlog is limited to 100 connections
your mercy for graceful operations on workers is 60 seconds
mapped 218304 bytes (213 KB) for 2 cores
*** Operational MODE: preforking ***
added /data/www/code/ to pythonpath.
WSGI app 0 (mountpoint='') ready in 0 seconds on interpreter 0x1ca10f0 pid: 13249 (default app)
mountpoint  already configured. skip.
*** uWSGI is running in multiple interpreter mode ***
spawned uWSGI master process (pid: 13249)
spawned uWSGI worker 1 (pid: 13255, cores: 1)
spawned uWSGI worker 2 (pid: 13256, cores: 1)
[pid: 13256|app: 0|req: 1/1] 192.168.1.16 () {42 vars in 793 bytes} [Tue Mar 14 14:01:16 2017] GET / => generated 3156 bytes in 44 msecs (HTTP/1.1 200) 3 headers in 283 bytes (1 switches on core 0)
[pid: 13256|app: 0|req: 2/2] 192.168.1.16 () {50 vars in 979 bytes} [Tue Mar 14 14:01:22 2017] POST / => generated 217 bytes in 375 msecs (HTTP/1.1 302) 4 headers in 606 bytes (1 switches on core 0)
[pid: 13256|app: 0|req: 3/3] 192.168.1.16 () {46 vars in 1152 bytes} [Tue Mar 14 14:01:22 2017] GET /log/ => generated 11839 bytes in 68 msecs (HTTP/1.1 200) 3 headers in 490 bytes (1 switches on core 0)
[pid: 13256|app: 0|req: 4/4] 192.168.1.16 () {44 vars in 1052 bytes} [Tue Mar 14 14:01:24 2017] GET /user/ => generated 13000 bytes in 66 msecs (HTTP/1.1 200) 2 headers in 82 bytes (1 switches on core 0)
[pid: 13256|app: 0|req: 5/5] 192.168.1.16 () {44 vars in 1057 bytes} [Tue Mar 14 14:01:25 2017] GET /domain/ => generated 9042 bytes in 65 msecs (HTTP/1.1 200) 2 headers in 81 bytes (1 switches on core 0)
[pid: 13256|app: 0|req: 6/6] 192.168.1.16 () {44 vars in 1053 bytes} [Tue Mar 14 14:01:26 2017] GET /log/ => generated 11614 bytes in 57 msecs (HTTP/1.1 200) 2 headers in 82 bytes (1 switches on core 0)
[pid: 13256|app: 0|req: 7/7] 192.168.1.16 () {40 vars in 610 bytes} [Tue Mar 14 14:11:33 2017] GET / => generated 3156 bytes in 4 msecs (HTTP/1.1 200) 3 headers in 283 bytes (1 switches on core 0)
[pid: 13255|app: 0|req: 1/8] 192.168.1.16 () {40 vars in 543 bytes} [Tue Mar 14 14:11:34 2017] GET /favicon.ico => generated 233 bytes in 18 msecs (HTTP/1.1 404) 2 headers in 72 bytes (1 switches on core 0)
[pid: 13255|app: 0|req: 2/9] 192.168.1.16 () {40 vars in 543 bytes} [Tue Mar 14 14:12:37 2017] GET /favicon.ico => generated 233 bytes in 0 msecs (HTTP/1.1 404) 2 headers in 72 bytes (1 switches on core 0)
[pid: 13255|app: 0|req: 3/10] 192.168.1.16 () {42 vars in 795 bytes} [Tue Mar 14 14:14:45 2017] GET / => generated 3156 bytes in 41 msecs (HTTP/1.1 200) 3 headers in 283 bytes (1 switches on core 0)
[pid: 13255|app: 0|req: 4/11] 192.168.1.16 () {50 vars in 983 bytes} [Tue Mar 14 14:14:50 2017] POST / => generated 217 bytes in 318 msecs (HTTP/1.1 302) 4 headers in 608 bytes (1 switches on core 0)
[pid: 13255|app: 0|req: 5/12] 192.168.1.16 () {46 vars in 1156 bytes} [Tue Mar 14 14:14:50 2017] GET /log/ => generated 11839 bytes in 51 msecs (HTTP/1.1 200) 3 headers in 492 bytes (1 switches on core 0)
[pid: 13255|app: 0|req: 6/13] 192.168.1.16 () {44 vars in 1058 bytes} [Tue Mar 14 14:14:53 2017] GET /user/ => generated 13000 bytes in 50 msecs (HTTP/1.1 200) 2 headers in 82 bytes (1 switches on core 0)
[pid: 13255|app: 0|req: 7/14] 192.168.1.16 () {44 vars in 1063 bytes} [Tue Mar 14 14:14:54 2017] GET /domain/ => generated 9042 bytes in 49 msecs (HTTP/1.1 200) 2 headers in 81 bytes (1 switches on core 0)
[pid: 13255|app: 0|req: 8/15] 192.168.1.16 () {44 vars in 1061 bytes} [Tue Mar 14 14:14:55 2017] GET /user/ => generated 13000 bytes in 40 msecs (HTTP/1.1 200) 2 headers in 82 bytes (1 switches on core 0)
[pid: 13255|app: 0|req: 9/16] 192.168.1.16 () {44 vars in 1057 bytes} [Tue Mar 14 14:14:55 2017] GET /log/ => generated 11614 bytes in 40 msecs (HTTP/1.1 200) 2 headers in 82 bytes (1 switches on core 0)
[pid: 13255|app: 0|req: 10/17] 192.168.1.16 () {40 vars in 608 bytes} [Tue Mar 14 14:22:33 2017] GET / => generated 3156 bytes in 4 msecs (HTTP/1.1 200) 3 headers in 283 bytes (1 switches on core 0)
[pid: 13255|app: 0|req: 11/18] 192.168.1.16 () {40 vars in 541 bytes} [Tue Mar 14 14:22:33 2017] GET /favicon.ico => generated 233 bytes in 1 msecs (HTTP/1.1 404) 2 headers in 72 bytes (1 switches on core 0)
Traceback (most recent call last):
  File "/data/www/code/venv/lib/python2.7/site-packages/flask/app.py", line 1994, in __call__
    return self.wsgi_app(environ, start_response)
  File "/data/www/code/venv/lib/python2.7/site-packages/flask/app.py", line 1985, in wsgi_app
    response = self.handle_exception(e)
  File "/data/www/code/venv/lib/python2.7/site-packages/flask/app.py", line 1540, in handle_exception
    reraise(exc_type, exc_value, tb)
  File "/data/www/code/venv/lib/python2.7/site-packages/flask/app.py", line 1982, in wsgi_app
    response = self.full_dispatch_request()
  File "/data/www/code/venv/lib/python2.7/site-packages/flask/app.py", line 1614, in full_dispatch_request
    rv = self.handle_user_exception(e)
  File "/data/www/code/venv/lib/python2.7/site-packages/flask/app.py", line 1517, in handle_user_exception
    reraise(exc_type, exc_value, tb)
  File "/data/www/code/venv/lib/python2.7/site-packages/flask/app.py", line 1612, in full_dispatch_request
    rv = self.dispatch_request()
  File "/data/www/code/venv/lib/python2.7/site-packages/flask/app.py", line 1598, in dispatch_request
    return self.view_functions[rule.endpoint](**req.view_args)
  File "/data/www/code/app/views.py", line 33, in login
    user = User.find_one(form.username.data)
  File "/data/www/code/app/models.py", line 33, in find_one
    user = db.user.find_one({ 'name': username })
  File "/data/www/code/venv/lib/python2.7/site-packages/pymongo/collection.py", line 1102, in find_one
    for result in cursor.limit(-1):
  File "/data/www/code/venv/lib/python2.7/site-packages/pymongo/cursor.py", line 1114, in next
    if len(self.__data) or self._refresh():
  File "/data/www/code/venv/lib/python2.7/site-packages/pymongo/cursor.py", line 1036, in _refresh
    self.__collation))
  File "/data/www/code/venv/lib/python2.7/site-packages/pymongo/cursor.py", line 873, in __send_message
    **kwargs)
  File "/data/www/code/venv/lib/python2.7/site-packages/pymongo/mongo_client.py", line 905, in _send_message_with_response
    exhaust)
  File "/data/www/code/venv/lib/python2.7/site-packages/pymongo/mongo_client.py", line 916, in _reset_on_error
    return func(*args, **kwargs)
  File "/data/www/code/venv/lib/python2.7/site-packages/pymongo/server.py", line 136, in send_message_with_response
    response_data = sock_info.receive_message(1, request_id)
  File "/data/www/code/venv/lib/python2.7/site-packages/pymongo/pool.py", line 452, in receive_message
    self._raise_connection_failure(error)
  File "/data/www/code/venv/lib/python2.7/site-packages/pymongo/pool.py", line 550, in _raise_connection_failure
    _raise_connection_failure(self.address, error)
  File "/data/www/code/venv/lib/python2.7/site-packages/pymongo/pool.py", line 211, in _raise_connection_failure
    raise AutoReconnect(msg)
pymongo.errors.AutoReconnect: 123.206.14.167:27017: [Errno 110] Connection timed out
[pid: 13256|app: 0|req: 8/19] 192.168.1.16 () {50 vars in 983 bytes} [Tue Mar 14 14:11:37 2017] POST / => generated 0 bytes in 951636 msecs (HTTP/1.1 500) 0 headers in 0 bytes (0 switches on core 0)
[pid: 13256|app: 0|req: 9/20] 192.168.1.16 () {50 vars in 979 bytes} [Tue Mar 14 14:27:29 2017] POST / => generated 217 bytes in 663 msecs (HTTP/1.1 302) 4 headers in 606 bytes (1 switches on core 0)
[pid: 13256|app: 0|req: 10/21] 192.168.1.16 () {50 vars in 979 bytes} [Tue Mar 14 14:27:29 2017] POST / => generated 217 bytes in 56 msecs (HTTP/1.1 302) 4 headers in 606 bytes (1 switches on core 0)
[pid: 13256|app: 0|req: 11/22] 192.168.1.16 () {50 vars in 979 bytes} [Tue Mar 14 14:27:30 2017] POST / => generated 217 bytes in 56 msecs (HTTP/1.1 302) 4 headers in 606 bytes (1 switches on core 0)
[pid: 13256|app: 0|req: 12/23] 192.168.1.16 () {50 vars in 979 bytes} [Tue Mar 14 14:27:30 2017] POST / => generated 217 bytes in 54 msecs (HTTP/1.1 302) 4 headers in 606 bytes (1 switches on core 0)
[pid: 13256|app: 0|req: 13/24] 192.168.1.16 () {50 vars in 979 bytes} [Tue Mar 14 14:27:30 2017] POST / => generated 217 bytes in 55 msecs (HTTP/1.1 302) 4 headers in 606 bytes (1 switches on core 0)
[pid: 13256|app: 0|req: 14/25] 192.168.1.16 () {40 vars in 541 bytes} [Tue Mar 14 14:27:30 2017] GET /favicon.ico => generated 233 bytes in 13 msecs (HTTP/1.1 404) 2 headers in 72 bytes (1 switches on core 0)
[pid: 13256|app: 0|req: 15/26] 192.168.1.16 () {42 vars in 793 bytes} [Tue Mar 14 14:27:30 2017] GET / => generated 3156 bytes in 3 msecs (HTTP/1.1 200) 3 headers in 283 bytes (1 switches on core 0)
[pid: 13256|app: 0|req: 16/27] 192.168.1.16 () {42 vars in 793 bytes} [Tue Mar 14 14:27:30 2017] GET / => generated 3156 bytes in 2 msecs (HTTP/1.1 200) 3 headers in 283 bytes (1 switches on core 0)
Traceback (most recent call last):
  File "/data/www/code/venv/lib/python2.7/site-packages/flask/app.py", line 1994, in __call__
    return self.wsgi_app(environ, start_response)
  File "/data/www/code/venv/lib/python2.7/site-packages/flask/app.py", line 1985, in wsgi_app
    response = self.handle_exception(e)
  File "/data/www/code/venv/lib/python2.7/site-packages/flask/app.py", line 1540, in handle_exception
    reraise(exc_type, exc_value, tb)
  File "/data/www/code/venv/lib/python2.7/site-packages/flask/app.py", line 1982, in wsgi_app
    response = self.full_dispatch_request()
  File "/data/www/code/venv/lib/python2.7/site-packages/flask/app.py", line 1614, in full_dispatch_request
    rv = self.handle_user_exception(e)
  File "/data/www/code/venv/lib/python2.7/site-packages/flask/app.py", line 1517, in handle_user_exception
    reraise(exc_type, exc_value, tb)
  File "/data/www/code/venv/lib/python2.7/site-packages/flask/app.py", line 1612, in full_dispatch_request
    rv = self.dispatch_request()
  File "/data/www/code/venv/lib/python2.7/site-packages/flask/app.py", line 1598, in dispatch_request
    return self.view_functions[rule.endpoint](**req.view_args)
  File "/data/www/code/app/views.py", line 33, in login
    user = User.find_one(form.username.data)
  File "/data/www/code/app/models.py", line 33, in find_one
    user = db.user.find_one({ 'name': username })
  File "/data/www/code/venv/lib/python2.7/site-packages/pymongo/collection.py", line 1102, in find_one
    for result in cursor.limit(-1):
  File "/data/www/code/venv/lib/python2.7/site-packages/pymongo/cursor.py", line 1114, in next
    if len(self.__data) or self._refresh():
  File "/data/www/code/venv/lib/python2.7/site-packages/pymongo/cursor.py", line 1036, in _refresh
    self.__collation))
  File "/data/www/code/venv/lib/python2.7/site-packages/pymongo/cursor.py", line 873, in __send_message
    **kwargs)
  File "/data/www/code/venv/lib/python2.7/site-packages/pymongo/mongo_client.py", line 905, in _send_message_with_response
    exhaust)
  File "/data/www/code/venv/lib/python2.7/site-packages/pymongo/mongo_client.py", line 916, in _reset_on_error
    return func(*args, **kwargs)
  File "/data/www/code/venv/lib/python2.7/site-packages/pymongo/server.py", line 136, in send_message_with_response
    response_data = sock_info.receive_message(1, request_id)
  File "/data/www/code/venv/lib/python2.7/site-packages/pymongo/pool.py", line 452, in receive_message
    self._raise_connection_failure(error)
  File "/data/www/code/venv/lib/python2.7/site-packages/pymongo/pool.py", line 550, in _raise_connection_failure
    _raise_connection_failure(self.address, error)
  File "/data/www/code/venv/lib/python2.7/site-packages/pymongo/pool.py", line 211, in _raise_connection_failure
    raise AutoReconnect(msg)
pymongo.errors.AutoReconnect: 123.206.14.167:27017: [Errno 110] Connection timed out
[pid: 13255|app: 0|req: 12/28] 192.168.1.16 () {50 vars in 979 bytes} [Tue Mar 14 14:22:37 2017] POST / => generated 0 bytes in 943149 msecs (HTTP/1.1 500) 0 headers in 0 bytes (0 switches on core 0)
[pid: 13255|app: 0|req: 13/29] 192.168.1.16 () {42 vars in 793 bytes} [Tue Mar 14 14:53:55 2017] GET / => generated 3156 bytes in 5 msecs (HTTP/1.1 200) 3 headers in 283 bytes (1 switches on core 0)
[pid: 13255|app: 0|req: 14/30] 192.168.1.16 () {50 vars in 979 bytes} [Tue Mar 14 14:54:00 2017] POST / => generated 217 bytes in 15276 msecs (HTTP/1.1 302) 4 headers in 606 bytes (1 switches on core 0)
[pid: 13255|app: 0|req: 15/31] 192.168.1.16 () {46 vars in 1152 bytes} [Tue Mar 14 14:54:16 2017] GET /log/ => generated 11835 bytes in 55 msecs (HTTP/1.1 200) 3 headers in 492 bytes (1 switches on core 0)
Traceback (most recent call last):
  File "/data/www/code/venv/lib/python2.7/site-packages/flask/app.py", line 1994, in __call__
    return self.wsgi_app(environ, start_response)
  File "/data/www/code/venv/lib/python2.7/site-packages/flask/app.py", line 1985, in wsgi_app
    response = self.handle_exception(e)
  File "/data/www/code/venv/lib/python2.7/site-packages/flask/app.py", line 1540, in handle_exception
    reraise(exc_type, exc_value, tb)
  File "/data/www/code/venv/lib/python2.7/site-packages/flask/app.py", line 1982, in wsgi_app
    response = self.full_dispatch_request()
  File "/data/www/code/venv/lib/python2.7/site-packages/flask/app.py", line 1614, in full_dispatch_request
    rv = self.handle_user_exception(e)
  File "/data/www/code/venv/lib/python2.7/site-packages/flask/app.py", line 1517, in handle_user_exception
    reraise(exc_type, exc_value, tb)
  File "/data/www/code/venv/lib/python2.7/site-packages/flask/app.py", line 1612, in full_dispatch_request
    rv = self.dispatch_request()
  File "/data/www/code/venv/lib/python2.7/site-packages/flask/app.py", line 1598, in dispatch_request
    return self.view_functions[rule.endpoint](**req.view_args)
  File "/data/www/code/venv/lib/python2.7/site-packages/flask_login/utils.py", line 228, in decorated_view
    return func(*args, **kwargs)
  File "/data/www/code/app/views.py", line 64, in user
    users, count = User.find(10, page)
  File "/data/www/code/app/models.py", line 40, in find
    count = db.user.find().count()
  File "/data/www/code/venv/lib/python2.7/site-packages/pymongo/cursor.py", line 711, in count
    return self.__collection._count(cmd, self.__collation)
  File "/data/www/code/venv/lib/python2.7/site-packages/pymongo/collection.py", line 1310, in _count
    collation=collation)
  File "/data/www/code/venv/lib/python2.7/site-packages/pymongo/collection.py", line 232, in _command
    collation=collation)
  File "/data/www/code/venv/lib/python2.7/site-packages/pymongo/pool.py", line 424, in command
    self._raise_connection_failure(error)
  File "/data/www/code/venv/lib/python2.7/site-packages/pymongo/pool.py", line 550, in _raise_connection_failure
    _raise_connection_failure(self.address, error)
  File "/data/www/code/venv/lib/python2.7/site-packages/pymongo/pool.py", line 211, in _raise_connection_failure
    raise AutoReconnect(msg)
pymongo.errors.AutoReconnect: 123.206.14.167:27017: [Errno 110] Connection timed out
[pid: 13255|app: 0|req: 16/32] 192.168.1.16 () {44 vars in 1054 bytes} [Tue Mar 14 14:59:35 2017] GET /user/ => generated 0 bytes in 943107 msecs (HTTP/1.1 500) 0 headers in 0 bytes (0 switches on core 0)
Traceback (most recent call last):
  File "/data/www/code/venv/lib/python2.7/site-packages/flask/app.py", line 1994, in __call__
    return self.wsgi_app(environ, start_response)
  File "/data/www/code/venv/lib/python2.7/site-packages/flask/app.py", line 1985, in wsgi_app
    response = self.handle_exception(e)
  File "/data/www/code/venv/lib/python2.7/site-packages/flask/app.py", line 1540, in handle_exception
    reraise(exc_type, exc_value, tb)
  File "/data/www/code/venv/lib/python2.7/site-packages/flask/app.py", line 1982, in wsgi_app
    response = self.full_dispatch_request()
  File "/data/www/code/venv/lib/python2.7/site-packages/flask/app.py", line 1614, in full_dispatch_request
    rv = self.handle_user_exception(e)
  File "/data/www/code/venv/lib/python2.7/site-packages/flask/app.py", line 1517, in handle_user_exception
    reraise(exc_type, exc_value, tb)
  File "/data/www/code/venv/lib/python2.7/site-packages/flask/app.py", line 1612, in full_dispatch_request
    rv = self.dispatch_request()
  File "/data/www/code/venv/lib/python2.7/site-packages/flask/app.py", line 1598, in dispatch_request
    return self.view_functions[rule.endpoint](**req.view_args)
  File "/data/www/code/venv/lib/python2.7/site-packages/flask_login/utils.py", line 228, in decorated_view
    return func(*args, **kwargs)
  File "/data/www/code/app/views.py", line 157, in log
    logs, count = Log.find(10, page)
  File "/data/www/code/app/models.py", line 130, in find
    count = db.log.find().count()
  File "/data/www/code/venv/lib/python2.7/site-packages/pymongo/cursor.py", line 711, in count
    return self.__collection._count(cmd, self.__collation)
  File "/data/www/code/venv/lib/python2.7/site-packages/pymongo/collection.py", line 1310, in _count
    collation=collation)
  File "/data/www/code/venv/lib/python2.7/site-packages/pymongo/collection.py", line 232, in _command
    collation=collation)
  File "/data/www/code/venv/lib/python2.7/site-packages/pymongo/pool.py", line 424, in command
    self._raise_connection_failure(error)
  File "/data/www/code/venv/lib/python2.7/site-packages/pymongo/pool.py", line 550, in _raise_connection_failure
    _raise_connection_failure(self.address, error)
  File "/data/www/code/venv/lib/python2.7/site-packages/pymongo/pool.py", line 211, in _raise_connection_failure
    raise AutoReconnect(msg)
pymongo.errors.AutoReconnect: 123.206.14.167:27017: [Errno 110] Connection timed out
[pid: 13256|app: 0|req: 17/33] 192.168.1.16 () {44 vars in 1052 bytes} [Tue Mar 14 14:59:37 2017] GET /log/ => generated 0 bytes in 943251 msecs (HTTP/1.1 500) 0 headers in 0 bytes (0 switches on core 0)
[pid: 13255|app: 0|req: 17/34] 192.168.1.16 () {40 vars in 610 bytes} [Tue Mar 14 15:20:33 2017] GET / => generated 3156 bytes in 4 msecs (HTTP/1.1 200) 3 headers in 283 bytes (1 switches on core 0)
[pid: 13256|app: 0|req: 18/35] 192.168.1.16 () {40 vars in 543 bytes} [Tue Mar 14 15:20:34 2017] GET /favicon.ico => generated 233 bytes in 1 msecs (HTTP/1.1 404) 2 headers in 72 bytes (1 switches on core 0)
[pid: 13255|app: 0|req: 18/36] 192.168.1.16 () {50 vars in 983 bytes} [Tue Mar 14 15:20:37 2017] POST / => generated 217 bytes in 16723 msecs (HTTP/1.1 302) 4 headers in 606 bytes (1 switches on core 0)
[pid: 13256|app: 0|req: 19/37] 192.168.1.16 () {46 vars in 1154 bytes} [Tue Mar 14 15:20:54 2017] GET /log/ => generated 11835 bytes in 20354 msecs (HTTP/1.1 200) 3 headers in 493 bytes (1 switches on core 0)
[pid: 13255|app: 0|req: 19/38] 192.168.1.16 () {40 vars in 543 bytes} [Tue Mar 14 15:21:14 2017] GET /favicon.ico => generated 233 bytes in 1 msecs (HTTP/1.1 404) 2 headers in 72 bytes (1 switches on core 0)
[pid: 13256|app: 0|req: 20/39] 192.168.1.16 () {44 vars in 1059 bytes} [Tue Mar 14 15:23:23 2017] GET /user/ => generated 13000 bytes in 40 msecs (HTTP/1.1 200) 2 headers in 82 bytes (1 switches on core 0)
[pid: 13256|app: 0|req: 21/40] 192.168.1.16 () {44 vars in 1064 bytes} [Tue Mar 14 15:23:24 2017] GET /domain/ => generated 9042 bytes in 38 msecs (HTTP/1.1 200) 2 headers in 81 bytes (1 switches on core 0)
[pid: 13255|app: 0|req: 20/41] 192.168.1.16 () {44 vars in 1060 bytes} [Tue Mar 14 15:23:25 2017] GET /log/ => generated 11610 bytes in 40 msecs (HTTP/1.1 200) 2 headers in 82 bytes (1 switches on core 0)
[pid: 13255|app: 0|req: 21/42] 192.168.1.16 () {40 vars in 610 bytes} [Tue Mar 14 15:26:25 2017] GET / => generated 3156 bytes in 4 msecs (HTTP/1.1 200) 3 headers in 283 bytes (1 switches on core 0)
[pid: 13255|app: 0|req: 22/43] 192.168.1.16 () {40 vars in 543 bytes} [Tue Mar 14 15:26:25 2017] GET /favicon.ico => generated 233 bytes in 0 msecs (HTTP/1.1 404) 2 headers in 72 bytes (1 switches on core 0)
[pid: 13255|app: 0|req: 23/44] 192.168.1.16 () {50 vars in 983 bytes} [Tue Mar 14 15:26:29 2017] POST / => generated 217 bytes in 61 msecs (HTTP/1.1 302) 4 headers in 604 bytes (1 switches on core 0)
[pid: 13256|app: 0|req: 22/45] 192.168.1.16 () {46 vars in 1152 bytes} [Tue Mar 14 15:26:29 2017] GET /log/ => generated 11835 bytes in 44 msecs (HTTP/1.1 200) 3 headers in 488 bytes (1 switches on core 0)
[pid: 13255|app: 0|req: 24/46] 192.168.1.16 () {40 vars in 543 bytes} [Tue Mar 14 15:26:29 2017] GET /favicon.ico => generated 233 bytes in 0 msecs (HTTP/1.1 404) 2 headers in 72 bytes (1 switches on core 0)
[pid: 13256|app: 0|req: 23/47] 192.168.1.16 () {44 vars in 1054 bytes} [Tue Mar 14 15:27:24 2017] GET /user/ => generated 13000 bytes in 39 msecs (HTTP/1.1 200) 2 headers in 82 bytes (1 switches on core 0)
[pid: 13256|app: 0|req: 24/48] 192.168.1.16 () {44 vars in 1059 bytes} [Tue Mar 14 15:27:24 2017] GET /domain/ => generated 9042 bytes in 41 msecs (HTTP/1.1 200) 2 headers in 81 bytes (1 switches on core 0)
[pid: 13255|app: 0|req: 25/49] 192.168.1.16 () {44 vars in 1055 bytes} [Tue Mar 14 15:27:25 2017] GET /log/ => generated 11610 bytes in 252 msecs (HTTP/1.1 200) 2 headers in 82 bytes (1 switches on core 0)
[pid: 13255|app: 0|req: 26/50] 192.168.1.16 () {44 vars in 1054 bytes} [Tue Mar 14 15:27:27 2017] GET /user/ => generated 13000 bytes in 40 msecs (HTTP/1.1 200) 2 headers in 82 bytes (1 switches on core 0)
[pid: 13255|app: 0|req: 27/51] 192.168.1.16 () {44 vars in 1059 bytes} [Tue Mar 14 15:27:28 2017] GET /domain/ => generated 9042 bytes in 39 msecs (HTTP/1.1 200) 2 headers in 81 bytes (1 switches on core 0)
[pid: 13256|app: 0|req: 25/52] 192.168.1.16 () {44 vars in 1090 bytes} [Tue Mar 14 15:27:56 2017] GET /user/settings/?u=admin => generated 8752 bytes in 33 msecs (HTTP/1.1 200) 2 headers in 81 bytes (1 switches on core 0)
[pid: 13256|app: 0|req: 26/53] 192.168.1.16 () {44 vars in 1076 bytes} [Tue Mar 14 15:28:03 2017] GET /domain/ => generated 9042 bytes in 41 msecs (HTTP/1.1 200) 2 headers in 81 bytes (1 switches on core 0)
warning: unable to access '/root/.config/git/attributes': Permission denied
warning: unable to access '/root/.config/git/ignore': Permission denied
Previous HEAD position was 01120ea... 110
HEAD is now at 672889e... 109
spawn /usr/bin/rsync -az --exclude=.git --delete /data/www/test/ root@192.168.1.25:/data/www/test/
ssh: connect to host 192.168.1.25 port 22: No route to host
rsync: connection unexpectedly closed (0 bytes received so far) [sender]
rsync error: unexplained error (code 255) at io.c(226) [sender=3.1.0]
[pid: 13256|app: 0|req: 27/54] 192.168.1.16 () {52 vars in 1218 bytes} [Tue Mar 14 15:28:17 2017] POST /domain/deploy/ => generated 6 bytes in 18133 msecs (HTTP/1.1 200) 3 headers in 549 bytes (1 switches on core 0)
[pid: 13256|app: 0|req: 28/55] 192.168.1.16 () {44 vars in 1141 bytes} [Tue Mar 14 15:28:36 2017] GET /domain/ => generated 9265 bytes in 42 msecs (HTTP/1.1 200) 3 headers in 487 bytes (1 switches on core 0)
SIGINT/SIGQUIT received...killing workers...
worker 1 buried after 1 seconds
worker 2 buried after 1 seconds
goodbye to uWSGI.
*** Starting uWSGI 2.0.14 (64bit) on [Tue Mar 14 15:43:29 2017] ***
compiled with version: 4.8.4 on 10 March 2017 11:44:01
os: Linux-3.13.0-32-generic #57-Ubuntu SMP Tue Jul 15 03:51:08 UTC 2014
nodename: ubuntu-web
machine: x86_64
clock source: unix
pcre jit disabled
detected number of CPU cores: 16
current working directory: /data/www/code/app
writing pidfile to /data/www/code//uwsgi.pid
detected binary path: /usr/local/bin/uwsgi
setgid() to 1003
set additional group 33 (www-data)
setuid() to 1003
chdir() to /data/www/code/
your processes number limit is 95816
your memory page size is 4096 bytes
detected max file descriptor number: 1000000
lock engine: pthread robust mutexes
thunder lock: disabled (you can enable it with --thunder-lock)
uwsgi socket 0 bound to TCP address 127.0.0.1:9090 fd 3
Python version: 2.7.6 (default, Oct 26 2016, 20:33:43)  [GCC 4.8.4]
Set PythonHome to /data/www/code/venv
Python main interpreter initialized at 0x93d1d0
python threads support enabled
your server socket listen backlog is limited to 100 connections
your mercy for graceful operations on workers is 60 seconds
mapped 311040 bytes (303 KB) for 8 cores
*** Operational MODE: preforking+threaded ***
added /data/www/code/ to pythonpath.
Traceback (most recent call last):
  File "/data/www/code/app/__init__.py", line 22, in <module>
    from app import views
  File "/data/www/code/app/views.py", line 8, in <module>
    from .models import User, Domain, Log
  File "/data/www/code/app/models.py", line 6, in <module>
    db = MongoClient(app.config['DATABASE_URI'], connect=False, max_pool_size=1).codeadmin
  File "/data/www/code/venv/lib/python2.7/site-packages/pymongo/mongo_client.py", line 422, in __init__
    for k, v in keyword_opts.items())
  File "/data/www/code/venv/lib/python2.7/site-packages/pymongo/mongo_client.py", line 422, in <genexpr>
    for k, v in keyword_opts.items())
  File "/data/www/code/venv/lib/python2.7/site-packages/pymongo/common.py", line 539, in validate
    value = validator(option, value)
  File "/data/www/code/venv/lib/python2.7/site-packages/pymongo/common.py", line 117, in raise_config_error
    raise ConfigurationError("Unknown option %s" % (key,))
pymongo.errors.ConfigurationError: Unknown option max_pool_size
unable to load app 0 (mountpoint='') (callable not found or import error)
Traceback (most recent call last):
  File "/data/www/code/manager.py", line 2, in <module>
    from app import app
  File "/data/www/code/app/__init__.py", line 22, in <module>
    from app import views
  File "/data/www/code/app/views.py", line 8, in <module>
    from .models import User, Domain, Log
  File "/data/www/code/app/models.py", line 6, in <module>
    db = MongoClient(app.config['DATABASE_URI'], connect=False, max_pool_size=1).codeadmin
  File "/data/www/code/venv/lib/python2.7/site-packages/pymongo/mongo_client.py", line 422, in __init__
    for k, v in keyword_opts.items())
  File "/data/www/code/venv/lib/python2.7/site-packages/pymongo/mongo_client.py", line 422, in <genexpr>
    for k, v in keyword_opts.items())
  File "/data/www/code/venv/lib/python2.7/site-packages/pymongo/common.py", line 539, in validate
    value = validator(option, value)
  File "/data/www/code/venv/lib/python2.7/site-packages/pymongo/common.py", line 117, in raise_config_error
    raise ConfigurationError("Unknown option %s" % (key,))
pymongo.errors.ConfigurationError: Unknown option max_pool_size
unable to load app 0 (mountpoint='') (callable not found or import error)
*** no app loaded. going in full dynamic mode ***
*** uWSGI is running in multiple interpreter mode ***
spawned uWSGI master process (pid: 13948)
spawned uWSGI worker 1 (pid: 13953, cores: 4)
spawned uWSGI worker 2 (pid: 13954, cores: 4)
--- no python application found, check your startup logs for errors ---
[pid: 13954|app: -1|req: -1/1] 192.168.1.16 () {44 vars in 1029 bytes} [Tue Mar 14 15:43:57 2017] GET / => generated 21 bytes in 0 msecs (HTTP/1.1 500) 2 headers in 83 bytes (0 switches on core 0)
--- no python application found, check your startup logs for errors ---
[pid: 13953|app: -1|req: -1/2] 192.168.1.16 () {44 vars in 1029 bytes} [Tue Mar 14 15:44:00 2017] GET / => generated 21 bytes in 0 msecs (HTTP/1.1 500) 2 headers in 83 bytes (0 switches on core 0)
--- no python application found, check your startup logs for errors ---
[pid: 13953|app: -1|req: -1/3] 192.168.1.16 () {44 vars in 1029 bytes} [Tue Mar 14 15:44:04 2017] GET / => generated 21 bytes in 0 msecs (HTTP/1.1 500) 2 headers in 83 bytes (0 switches on core 3)
--- no python application found, check your startup logs for errors ---
[pid: 13953|app: -1|req: -1/4] 192.168.1.16 () {40 vars in 610 bytes} [Tue Mar 14 15:44:34 2017] GET / => generated 21 bytes in 0 msecs (HTTP/1.1 500) 2 headers in 83 bytes (0 switches on core 2)
*** Starting uWSGI 2.0.14 (64bit) on [Tue Mar 14 15:46:36 2017] ***
compiled with version: 4.8.4 on 10 March 2017 11:44:01
os: Linux-3.13.0-32-generic #57-Ubuntu SMP Tue Jul 15 03:51:08 UTC 2014
nodename: ubuntu-web
machine: x86_64
clock source: unix
pcre jit disabled
detected number of CPU cores: 16
current working directory: /data/www/code
writing pidfile to /data/www/code//uwsgi.pid
detected binary path: /usr/local/bin/uwsgi
setgid() to 1003
set additional group 33 (www-data)
setuid() to 1003
chdir() to /data/www/code/
your processes number limit is 95816
your memory page size is 4096 bytes
detected max file descriptor number: 1000000
lock engine: pthread robust mutexes
thunder lock: disabled (you can enable it with --thunder-lock)
probably another instance of uWSGI is running on the same address (127.0.0.1:9090).
bind(): Address already in use [core/socket.c line 769]
--- no python application found, check your startup logs for errors ---
[pid: 13954|app: -1|req: -1/5] 192.168.1.16 () {40 vars in 610 bytes} [Tue Mar 14 15:46:49 2017] GET / => generated 21 bytes in 0 msecs (HTTP/1.1 500) 2 headers in 83 bytes (0 switches on core 1)
--- no python application found, check your startup logs for errors ---
[pid: 13953|app: -1|req: -1/6] 192.168.1.16 () {40 vars in 610 bytes} [Tue Mar 14 15:46:50 2017] GET / => generated 21 bytes in 0 msecs (HTTP/1.1 500) 2 headers in 83 bytes (0 switches on core 1)
--- no python application found, check your startup logs for errors ---
[pid: 13953|app: -1|req: -1/7] 192.168.1.16 () {40 vars in 610 bytes} [Tue Mar 14 15:46:51 2017] GET / => generated 21 bytes in 0 msecs (HTTP/1.1 500) 2 headers in 83 bytes (0 switches on core 3)
--- no python application found, check your startup logs for errors ---
[pid: 13953|app: -1|req: -1/8] 192.168.1.16 () {40 vars in 610 bytes} [Tue Mar 14 15:46:51 2017] GET / => generated 21 bytes in 0 msecs (HTTP/1.1 500) 2 headers in 83 bytes (0 switches on core 2)
*** Starting uWSGI 2.0.14 (64bit) on [Tue Mar 14 15:47:13 2017] ***
compiled with version: 4.8.4 on 10 March 2017 11:44:01
os: Linux-3.13.0-32-generic #57-Ubuntu SMP Tue Jul 15 03:51:08 UTC 2014
nodename: ubuntu-web
machine: x86_64
clock source: unix
pcre jit disabled
detected number of CPU cores: 16
current working directory: /data/www/code
writing pidfile to /data/www/code//uwsgi.pid
detected binary path: /usr/local/bin/uwsgi
setgid() to 1003
set additional group 33 (www-data)
setuid() to 1003
chdir() to /data/www/code/
your processes number limit is 95816
your memory page size is 4096 bytes
detected max file descriptor number: 1000000
lock engine: pthread robust mutexes
thunder lock: disabled (you can enable it with --thunder-lock)
probably another instance of uWSGI is running on the same address (127.0.0.1:9090).
bind(): Address already in use [core/socket.c line 769]
--- no python application found, check your startup logs for errors ---
[pid: 13953|app: -1|req: -1/9] 192.168.1.16 () {40 vars in 610 bytes} [Tue Mar 14 15:47:17 2017] GET / => generated 21 bytes in 0 msecs (HTTP/1.1 500) 2 headers in 83 bytes (0 switches on core 0)
--- no python application found, check your startup logs for errors ---
[pid: 13954|app: -1|req: -1/10] 192.168.1.16 () {40 vars in 610 bytes} [Tue Mar 14 16:23:54 2017] GET / => generated 21 bytes in 0 msecs (HTTP/1.1 500) 2 headers in 83 bytes (0 switches on core 2)
--- no python application found, check your startup logs for errors ---
[pid: 13953|app: -1|req: -1/11] 192.168.1.16 () {40 vars in 610 bytes} [Tue Mar 14 16:23:54 2017] GET / => generated 21 bytes in 0 msecs (HTTP/1.1 500) 2 headers in 83 bytes (0 switches on core 1)
--- no python application found, check your startup logs for errors ---
[pid: 13954|app: -1|req: -1/12] 192.168.1.16 () {40 vars in 610 bytes} [Tue Mar 14 16:23:55 2017] GET / => generated 21 bytes in 0 msecs (HTTP/1.1 500) 2 headers in 83 bytes (0 switches on core 1)
--- no python application found, check your startup logs for errors ---
[pid: 13954|app: -1|req: -1/13] 192.168.1.16 () {40 vars in 610 bytes} [Tue Mar 14 16:23:55 2017] GET / => generated 21 bytes in 0 msecs (HTTP/1.1 500) 2 headers in 83 bytes (0 switches on core 0)
--- no python application found, check your startup logs for errors ---
[pid: 13954|app: -1|req: -1/14] 192.168.1.16 () {40 vars in 610 bytes} [Tue Mar 14 16:23:55 2017] GET / => generated 21 bytes in 0 msecs (HTTP/1.1 500) 2 headers in 83 bytes (0 switches on core 2)
--- no python application found, check your startup logs for errors ---
[pid: 13954|app: -1|req: -1/15] 192.168.1.16 () {40 vars in 610 bytes} [Tue Mar 14 16:23:55 2017] GET / => generated 21 bytes in 0 msecs (HTTP/1.1 500) 2 headers in 83 bytes (0 switches on core 3)
--- no python application found, check your startup logs for errors ---
[pid: 13954|app: -1|req: -1/16] 192.168.1.16 () {40 vars in 610 bytes} [Tue Mar 14 16:23:55 2017] GET / => generated 21 bytes in 0 msecs (HTTP/1.1 500) 2 headers in 83 bytes (0 switches on core 1)
--- no python application found, check your startup logs for errors ---
[pid: 13954|app: -1|req: -1/17] 192.168.1.16 () {40 vars in 610 bytes} [Tue Mar 14 16:23:56 2017] GET / => generated 21 bytes in 0 msecs (HTTP/1.1 500) 2 headers in 83 bytes (0 switches on core 0)
--- no python application found, check your startup logs for errors ---
[pid: 13954|app: -1|req: -1/18] 192.168.1.16 () {40 vars in 610 bytes} [Tue Mar 14 16:23:56 2017] GET / => generated 21 bytes in 0 msecs (HTTP/1.1 500) 2 headers in 83 bytes (0 switches on core 2)
--- no python application found, check your startup logs for errors ---
[pid: 13954|app: -1|req: -1/19] 192.168.1.16 () {40 vars in 610 bytes} [Tue Mar 14 16:23:56 2017] GET / => generated 21 bytes in 0 msecs (HTTP/1.1 500) 2 headers in 83 bytes (0 switches on core 3)
--- no python application found, check your startup logs for errors ---
[pid: 13954|app: -1|req: -1/20] 192.168.1.16 () {40 vars in 610 bytes} [Tue Mar 14 16:23:58 2017] GET / => generated 21 bytes in 0 msecs (HTTP/1.1 500) 2 headers in 83 bytes (0 switches on core 1)
--- no python application found, check your startup logs for errors ---
[pid: 13954|app: -1|req: -1/21] 192.168.1.16 () {40 vars in 610 bytes} [Tue Mar 14 16:37:09 2017] GET / => generated 21 bytes in 0 msecs (HTTP/1.1 500) 2 headers in 83 bytes (0 switches on core 0)
Tue Mar 14 17:18:32 2017 - uWSGI worker 2 screams: UAAAAAAH my master disconnected: i will kill myself !!!
Tue Mar 14 17:18:32 2017 - uWSGI worker 1 screams: UAAAAAAH my master disconnected: i will kill myself !!!
Tue Mar 14 17:18:32 2017 - uWSGI worker 1 screams: UAAAAAAH my master disconnected: i will kill myself !!!
Tue Mar 14 17:18:32 2017 - uWSGI worker 1 screams: UAAAAAAH my master disconnected: i will kill myself !!!
Tue Mar 14 17:18:32 2017 - uWSGI worker 1 screams: UAAAAAAH my master disconnected: i will kill myself !!!
Tue Mar 14 17:18:32 2017 - uWSGI worker 2 screams: UAAAAAAH my master disconnected: i will kill myself !!!
Tue Mar 14 17:18:32 2017 - uWSGI worker 2 screams: UAAAAAAH my master disconnected: i will kill myself !!!
*** Starting uWSGI 2.0.14 (64bit) on [Tue Mar 14 17:18:47 2017] ***
compiled with version: 4.8.4 on 10 March 2017 11:44:01
os: Linux-3.13.0-32-generic #57-Ubuntu SMP Tue Jul 15 03:51:08 UTC 2014
nodename: ubuntu-web
machine: x86_64
clock source: unix
pcre jit disabled
detected number of CPU cores: 16
current working directory: /data/www/code
writing pidfile to /data/www/code//uwsgi.pid
detected binary path: /usr/local/bin/uwsgi
setgid() to 1003
set additional group 33 (www-data)
setuid() to 1003
chdir() to /data/www/code/
your processes number limit is 95816
your memory page size is 4096 bytes
detected max file descriptor number: 1000000
lock engine: pthread robust mutexes
thunder lock: disabled (you can enable it with --thunder-lock)
uwsgi socket 0 bound to TCP address 127.0.0.1:9090 fd 3
Python version: 2.7.6 (default, Oct 26 2016, 20:33:43)  [GCC 4.8.4]
Set PythonHome to /data/www/code/venv
Python main interpreter initialized at 0x17ec0e0
python threads support enabled
your server socket listen backlog is limited to 100 connections
your mercy for graceful operations on workers is 60 seconds
mapped 311040 bytes (303 KB) for 8 cores
*** Operational MODE: preforking+threaded ***
added /data/www/code/ to pythonpath.
Traceback (most recent call last):
  File "/data/www/code/app/__init__.py", line 22, in <module>
    from app import views
  File "/data/www/code/app/views.py", line 8, in <module>
    from .models import User, Domain, Log
  File "/data/www/code/app/models.py", line 6, in <module>
    db = MongoClient(app.config['DATABASE_URI'], max_pool_size=100).codeadmin
  File "/data/www/code/venv/lib/python2.7/site-packages/pymongo/mongo_client.py", line 422, in __init__
    for k, v in keyword_opts.items())
  File "/data/www/code/venv/lib/python2.7/site-packages/pymongo/mongo_client.py", line 422, in <genexpr>
    for k, v in keyword_opts.items())
  File "/data/www/code/venv/lib/python2.7/site-packages/pymongo/common.py", line 539, in validate
    value = validator(option, value)
  File "/data/www/code/venv/lib/python2.7/site-packages/pymongo/common.py", line 117, in raise_config_error
    raise ConfigurationError("Unknown option %s" % (key,))
pymongo.errors.ConfigurationError: Unknown option max_pool_size
unable to load app 0 (mountpoint='') (callable not found or import error)
Traceback (most recent call last):
  File "/data/www/code/manager.py", line 2, in <module>
    from app import app
  File "/data/www/code/app/__init__.py", line 22, in <module>
    from app import views
  File "/data/www/code/app/views.py", line 8, in <module>
    from .models import User, Domain, Log
  File "/data/www/code/app/models.py", line 6, in <module>
    db = MongoClient(app.config['DATABASE_URI'], max_pool_size=100).codeadmin
  File "/data/www/code/venv/lib/python2.7/site-packages/pymongo/mongo_client.py", line 422, in __init__
    for k, v in keyword_opts.items())
  File "/data/www/code/venv/lib/python2.7/site-packages/pymongo/mongo_client.py", line 422, in <genexpr>
    for k, v in keyword_opts.items())
  File "/data/www/code/venv/lib/python2.7/site-packages/pymongo/common.py", line 539, in validate
    value = validator(option, value)
  File "/data/www/code/venv/lib/python2.7/site-packages/pymongo/common.py", line 117, in raise_config_error
    raise ConfigurationError("Unknown option %s" % (key,))
pymongo.errors.ConfigurationError: Unknown option max_pool_size
unable to load app 0 (mountpoint='') (callable not found or import error)
*** no app loaded. going in full dynamic mode ***
*** uWSGI is running in multiple interpreter mode ***
spawned uWSGI master process (pid: 14614)
spawned uWSGI worker 1 (pid: 14619, cores: 4)
spawned uWSGI worker 2 (pid: 14620, cores: 4)
--- no python application found, check your startup logs for errors ---
[pid: 14619|app: -1|req: -1/1] 192.168.1.16 () {40 vars in 610 bytes} [Tue Mar 14 17:19:04 2017] GET / => generated 21 bytes in 0 msecs (HTTP/1.1 500) 2 headers in 83 bytes (0 switches on core 0)
--- no python application found, check your startup logs for errors ---
[pid: 14619|app: -1|req: -1/2] 192.168.1.16 () {40 vars in 610 bytes} [Tue Mar 14 17:19:05 2017] GET / => generated 21 bytes in 0 msecs (HTTP/1.1 500) 2 headers in 83 bytes (0 switches on core 1)
--- no python application found, check your startup logs for errors ---
[pid: 14619|app: -1|req: -1/3] 192.168.1.16 () {40 vars in 610 bytes} [Tue Mar 14 17:19:07 2017] GET / => generated 21 bytes in 0 msecs (HTTP/1.1 500) 2 headers in 83 bytes (0 switches on core 2)
--- no python application found, check your startup logs for errors ---
[pid: 14620|app: -1|req: -1/4] 192.168.1.16 () {40 vars in 610 bytes} [Tue Mar 14 17:19:41 2017] GET / => generated 21 bytes in 0 msecs (HTTP/1.1 500) 2 headers in 83 bytes (0 switches on core 0)
--- no python application found, check your startup logs for errors ---
[pid: 14620|app: -1|req: -1/5] 192.168.1.16 () {40 vars in 610 bytes} [Tue Mar 14 17:19:42 2017] GET / => generated 21 bytes in 0 msecs (HTTP/1.1 500) 2 headers in 83 bytes (0 switches on core 3)
--- no python application found, check your startup logs for errors ---
[pid: 14619|app: -1|req: -1/6] 192.168.1.16 () {40 vars in 610 bytes} [Tue Mar 14 17:19:42 2017] GET / => generated 21 bytes in 0 msecs (HTTP/1.1 500) 2 headers in 83 bytes (0 switches on core 3)
--- no python application found, check your startup logs for errors ---
[pid: 14620|app: -1|req: -1/7] 192.168.1.16 () {40 vars in 610 bytes} [Tue Mar 14 17:19:42 2017] GET / => generated 21 bytes in 0 msecs (HTTP/1.1 500) 2 headers in 83 bytes (0 switches on core 1)
--- no python application found, check your startup logs for errors ---
[pid: 14619|app: -1|req: -1/8] 192.168.1.16 () {40 vars in 610 bytes} [Tue Mar 14 17:19:42 2017] GET / => generated 21 bytes in 0 msecs (HTTP/1.1 500) 2 headers in 83 bytes (0 switches on core 2)
--- no python application found, check your startup logs for errors ---
[pid: 14619|app: -1|req: -1/9] 192.168.1.16 () {40 vars in 610 bytes} [Tue Mar 14 17:19:42 2017] GET / => generated 21 bytes in 0 msecs (HTTP/1.1 500) 2 headers in 83 bytes (0 switches on core 1)
*** Starting uWSGI 2.0.14 (64bit) on [Tue Mar 14 17:19:48 2017] ***
compiled with version: 4.8.4 on 10 March 2017 11:44:01
os: Linux-3.13.0-32-generic #57-Ubuntu SMP Tue Jul 15 03:51:08 UTC 2014
nodename: ubuntu-web
machine: x86_64
clock source: unix
pcre jit disabled
detected number of CPU cores: 16
current working directory: /data/www/code
writing pidfile to /data/www/code//uwsgi.pid
detected binary path: /usr/local/bin/uwsgi
setgid() to 1003
set additional group 33 (www-data)
setuid() to 1003
chdir() to /data/www/code/
your processes number limit is 95816
your memory page size is 4096 bytes
detected max file descriptor number: 1000000
lock engine: pthread robust mutexes
thunder lock: disabled (you can enable it with --thunder-lock)
probably another instance of uWSGI is running on the same address (127.0.0.1:9090).
bind(): Address already in use [core/socket.c line 769]
Tue Mar 14 17:21:31 2017 - uWSGI worker 1 screams: UAAAAAAH my master disconnected: i will kill myself !!!
Tue Mar 14 17:21:31 2017 - uWSGI worker 2 screams: UAAAAAAH my master disconnected: i will kill myself !!!
Tue Mar 14 17:21:31 2017 - uWSGI worker 2 screams: UAAAAAAH my master disconnected: i will kill myself !!!
Tue Mar 14 17:21:31 2017 - uWSGI worker 2 screams: UAAAAAAH my master disconnected: i will kill myself !!!
Tue Mar 14 17:21:31 2017 - uWSGI worker 1 screams: UAAAAAAH my master disconnected: i will kill myself !!!
*** Starting uWSGI 2.0.14 (64bit) on [Tue Mar 14 17:23:11 2017] ***
compiled with version: 4.8.4 on 10 March 2017 11:44:01
os: Linux-3.13.0-32-generic #57-Ubuntu SMP Tue Jul 15 03:51:08 UTC 2014
nodename: ubuntu-web
machine: x86_64
clock source: unix
pcre jit disabled
detected number of CPU cores: 16
current working directory: /data/www/code
writing pidfile to /data/www/code//uwsgi.pid
detected binary path: /usr/local/bin/uwsgi
setgid() to 1003
set additional group 33 (www-data)
setuid() to 1003
chdir() to /data/www/code/
your processes number limit is 95816
your memory page size is 4096 bytes
detected max file descriptor number: 1000000
lock engine: pthread robust mutexes
thunder lock: disabled (you can enable it with --thunder-lock)
uwsgi socket 0 bound to TCP address 127.0.0.1:9090 fd 3
Python version: 2.7.6 (default, Oct 26 2016, 20:33:43)  [GCC 4.8.4]
Set PythonHome to /data/www/code/venv
Python main interpreter initialized at 0x9f80e0
python threads support enabled
your server socket listen backlog is limited to 100 connections
your mercy for graceful operations on workers is 60 seconds
mapped 311040 bytes (303 KB) for 8 cores
*** Operational MODE: preforking+threaded ***
added /data/www/code/ to pythonpath.
WSGI app 0 (mountpoint='') ready in 0 seconds on interpreter 0x9f80e0 pid: 14667 (default app)
mountpoint  already configured. skip.
*** uWSGI is running in multiple interpreter mode ***
spawned uWSGI master process (pid: 14667)
spawned uWSGI worker 1 (pid: 14674, cores: 4)
spawned uWSGI worker 2 (pid: 14675, cores: 4)
